2020-12-22 10:57:15,437 - D:\ZYCami_00\PO\Base_page.py[line:31] - ERROR: ('xpath', '//android.widget.FrameLayout[@content-desc="Me"]/android.widget.ImageView')元素可见失效，错误：Message: 

2020-12-22 12:08:03,714 - D:\ZYCami_00\Public\Caplictily.py[line:44] - ERROR: 错误：Message: An unknown server-side error occurred while processing the command. Original error: Error executing adbExec. Original error: 'Command ''C:\\Program Files (x86)\\Android\\android-sdk\\platform-tools\\adb.exe' -P 5037 -s 7HX0219918017044 install -g 'C:\\Program Files\\Appium\\resources\\app\\node_modules\\appium\\node_modules\\io.appium.settings\\apks\\settings_apk-debug.apk'' exited with code 1'; Stderr: 'adb: failed to install C:\Program Files\Appium\resources\app\node_modules\appium\node_modules\io.appium.settings\apks\settings_apk-debug.apk: Failure [INSTALL_FAILED_ABORTED: User rejected permissions]'; Code: '1'

2020-12-22 12:08:30,952 - D:\ZYCami_00\Public\Caplictily.py[line:44] - ERROR: 错误：('Connection aborted.', RemoteDisconnected('Remote end closed connection without response'))
2020-12-22 12:08:46,895 - D:\ZYCami_00\Public\Caplictily.py[line:44] - ERROR: 错误：HTTPConnectionPool(host='127.0.0.1', port=4723): Max retries exceeded with url: /wd/hub/session (Caused by NewConnectionError('<urllib3.connection.HTTPConnection object at 0x0000023F76AE0A48>: Failed to establish a new connection: [WinError 10061] 由于目标计算机积极拒绝，无法连接。'))
2020-12-22 12:08:46,899 - D:\ZYCami_00\PO\Base_page.py[line:31] - ERROR: ('xpath', '//android.widget.FrameLayout[@content-desc="Me"]/android.widget.ImageView')元素可见失效，错误：'NoneType' object has no attribute 'find_element'
2020-12-22 12:08:46,911 - D:\ZYCami_00\PO\Base_page.py[line:31] - ERROR: ('xpath', '//android.widget.FrameLayout[@content-desc="Me"]/android.widget.ImageView')元素可见失效，错误：'NoneType' object has no attribute 'find_element'
2020-12-22 12:09:19,702 - D:\ZYCami_00\Public\Caplictily.py[line:44] - ERROR: 错误：HTTPConnectionPool(host='127.0.0.1', port=4723): Max retries exceeded with url: /wd/hub/session (Caused by NewConnectionError('<urllib3.connection.HTTPConnection object at 0x0000027965E4FB48>: Failed to establish a new connection: [WinError 10061] 由于目标计算机积极拒绝，无法连接。'))
2020-12-22 12:11:01,755 - D:\ZYCami_00\Public\Caplictily.py[line:44] - ERROR: 错误：HTTPConnectionPool(host='127.0.0.1', port=4723): Max retries exceeded with url: /wd/hub/session (Caused by NewConnectionError('<urllib3.connection.HTTPConnection object at 0x000001CE65AA08C8>: Failed to establish a new connection: [WinError 10061] 由于目标计算机积极拒绝，无法连接。'))
2020-12-22 12:12:26,758 - D:\ZYCami_00\Public\Caplictily.py[line:44] - ERROR: 错误：HTTPConnectionPool(host='127.0.0.1', port=4723): Max retries exceeded with url: /wd/hub/session (Caused by NewConnectionError('<urllib3.connection.HTTPConnection object at 0x0000019E993A08C8>: Failed to establish a new connection: [WinError 10061] 由于目标计算机积极拒绝，无法连接。'))
