INFO	2020-12-28 09:23:49,589	[remote_connection.py:117]	Could not connect to port 4444 on host 127.0.0.1
INFO	2020-12-28 09:23:49,590	[remote_connection.py:136]	Could not get IP address for host: 127.0.0.1
WARNING	2020-12-28 09:23:51,619	[connectionpool.py:752]	Retrying (Retry(total=2, connect=None, read=None, redirect=None, status=None)) after connection broken by 'NewConnectionError('<urllib3.connection.HTTPConnection object at 0x000002235801A208>: Failed to establish a new connection: [WinError 10061] 由于目标计算机积极拒绝，无法连接。')': /wd/hub/session
WARNING	2020-12-28 09:23:53,648	[connectionpool.py:752]	Retrying (Retry(total=1, connect=None, read=None, redirect=None, status=None)) after connection broken by 'NewConnectionError('<urllib3.connection.HTTPConnection object at 0x000002235801AAC8>: Failed to establish a new connection: [WinError 10061] 由于目标计算机积极拒绝，无法连接。')': /wd/hub/session
WARNING	2020-12-28 09:23:55,667	[connectionpool.py:752]	Retrying (Retry(total=0, connect=None, read=None, redirect=None, status=None)) after connection broken by 'NewConnectionError('<urllib3.connection.HTTPConnection object at 0x00000223580362C8>: Failed to establish a new connection: [WinError 10061] 由于目标计算机积极拒绝，无法连接。')': /wd/hub/session
INFO	2020-12-28 09:24:13,019	[remote_connection.py:117]	Could not connect to port 4444 on host 127.0.0.1
INFO	2020-12-28 09:24:13,019	[remote_connection.py:136]	Could not get IP address for host: 127.0.0.1
WARNING	2020-12-28 09:24:15,051	[connectionpool.py:752]	Retrying (Retry(total=2, connect=None, read=None, redirect=None, status=None)) after connection broken by 'NewConnectionError('<urllib3.connection.HTTPConnection object at 0x0000018A5A18D188>: Failed to establish a new connection: [WinError 10061] 由于目标计算机积极拒绝，无法连接。')': /wd/hub/session
WARNING	2020-12-28 09:24:17,083	[connectionpool.py:752]	Retrying (Retry(total=1, connect=None, read=None, redirect=None, status=None)) after connection broken by 'NewConnectionError('<urllib3.connection.HTTPConnection object at 0x0000018A5A18DA88>: Failed to establish a new connection: [WinError 10061] 由于目标计算机积极拒绝，无法连接。')': /wd/hub/session
WARNING	2020-12-28 09:24:19,115	[connectionpool.py:752]	Retrying (Retry(total=0, connect=None, read=None, redirect=None, status=None)) after connection broken by 'NewConnectionError('<urllib3.connection.HTTPConnection object at 0x0000018A5A1A6288>: Failed to establish a new connection: [WinError 10061] 由于目标计算机积极拒绝，无法连接。')': /wd/hub/session
INFO	2020-12-28 09:29:07,057	[remote_connection.py:117]	Could not connect to port 4444 on host 127.0.0.1
INFO	2020-12-28 09:29:07,057	[remote_connection.py:136]	Could not get IP address for host: 127.0.0.1
WARNING	2020-12-28 09:29:09,097	[connectionpool.py:752]	Retrying (Retry(total=2, connect=None, read=None, redirect=None, status=None)) after connection broken by 'NewConnectionError('<urllib3.connection.HTTPConnection object at 0x0000028B664CDF88>: Failed to establish a new connection: [WinError 10061] 由于目标计算机积极拒绝，无法连接。')': /wd/hub/session
WARNING	2020-12-28 09:29:11,132	[connectionpool.py:752]	Retrying (Retry(total=1, connect=None, read=None, redirect=None, status=None)) after connection broken by 'NewConnectionError('<urllib3.connection.HTTPConnection object at 0x0000028B664DF8C8>: Failed to establish a new connection: [WinError 10061] 由于目标计算机积极拒绝，无法连接。')': /wd/hub/session
WARNING	2020-12-28 09:29:13,169	[connectionpool.py:752]	Retrying (Retry(total=0, connect=None, read=None, redirect=None, status=None)) after connection broken by 'NewConnectionError('<urllib3.connection.HTTPConnection object at 0x0000028B664F60C8>: Failed to establish a new connection: [WinError 10061] 由于目标计算机积极拒绝，无法连接。')': /wd/hub/session
